<?xml version="1.0" ?>
<!-- This file was autogenerated but we have modified quite a bit
Authors: Karl, Ankur

Karl did the dynamics compensation and obtained the following values for the index finger

Noise: 0.111576
Masses: 0.005, 0.125164, 0.131691, 0.0211922,
Rotor Inertia: 0.00386572, 0.00346965, 0.00433775, 0.00366413,
Viscous Friction: 0.0414019, 0.00587541, 0.010638, 0.0226948,
Coulomb Friction: 0.0523963, 0.0150275, 0.00616359, 0.0227036,
Mass Inertia:
5.1458e-05, 5.1458e-05, 6.125e-05, 0, 0, 0,
6.39979e-06, 8.88687e-05, 9.13751e-05, -3.26531e-06, 1.23963e-05, 2.07384e-05,
7.04217e-05, 3.95744e-05, 6.61125e-05, -9.64342e-05, 5.8796e-05, -3.62996e-05,
2.93743e-05, 7.21391e-05, 7.59731e-05, -3.51896e-05, -6.31225e-05, -9.25392e-07,

Center of Mass:
0, 0, 0,
0.027, 0, 0,
0.038, 0, 0,
0.029, 0, 0,

-->

<robot name="allegro" xmlns:xacro="http://www.ros.org/wiki/xacro">
  <material name="Black">
    <color rgba="0.0 0.0 0.0 1.0"/>
  </material>
  <material name="Blue">
    <color rgba="0.0 0.0 0.8 1.0"/>
  </material>
  <material name="Green">
    <color rgba="0.0 0.8 0.0 1.0"/>
  </material>
  <material name="Grey">
    <color rgba="0.4 0.4 0.4 1.0"/>
  </material>
  <material name="Orange">
    <color rgba="1.0 0.423529411765 0.0392156862745 1.0"/>
  </material>
  <material name="Brown">
    <color rgba="0.870588235294 0.811764705882 0.764705882353 1.0"/>
  </material>
  <material name="Red">
    <color rgba="0.8 0.0 0.0 1.0"/>
  </material>
  <material name="White">
    <color rgba="1.0 1.0 1.0 1.0"/>
  </material>
  <link name="base_link"/>
  <!-- ======================== BASE PARAMS ========================= -->
  <!-- ======================== FINGER PARAMS ======================== -->
  <!-- full height from joint to tip. when used,
       the radius of the finger tip sphere will be subtracted
       and one fixed link will be added for the tip. -->
  <!-- ========================= THUMB PARAMS ========================= -->
  <!-- ========================= LIMITS ========================= -->
  <!-- ============================================================================= -->
  <!-- BASE -->

  <link name="allegro_mount">
    <inertial>
      <mass value="0.05"/>
      <origin rpy="0 0 0" xyz="0 0 0"/>
      <inertia ixx="1e-4" ixy="0" ixz="0" iyy="1e-4" iyz="0" izz="1e-4"/>
    </inertial>
    <visual>
      <!-- <origin xyz="-0.0425 -0.0425 0" rpy="0 0 0" /> -->
      <origin rpy="0 0 0" xyz="0 0 0"/>
      <geometry>
        <mesh filename="meshes/mounts/allegro_mount.obj"/>
      </geometry>
      <material name="color_j7"/>
    </visual>
    <collision>
      <!-- <origin xyz="-0.0425 -0.0425 0" rpy="0 0 0" /> -->
      <origin rpy="0 0 0" xyz="0 0 0"/>
      <geometry>
        <mesh filename="meshes/mounts/allegro_mount.obj"/>
      </geometry>
    </collision>
  </link>
  <!-- <joint name="allegro_mount_joint1" type="fixed">
    
    <origin rpy="0 0 0" xyz="-0.00 -0.0 0.0"/>
    <parent link="iiwa7_link_ee"/>
    <child link="allegro_mount"/>

  </joint> -->
  <joint name="allegro_mount_joint" type="fixed">
    <!-- <origin xyz="0.065 0 0.0275" rpy="0 1.57 0" /> -->
    <origin rpy="0 -1.5708 0.785398" xyz="0.008219 -0.02063 0.08086"/>
    <parent link="allegro_mount"/>
    <child link="palm_link"/>

  </joint>
  
  <!-- BASE -->
  <link name="palm_link">
    <inertial>
      <mass value="0.4154"/>
      <origin rpy="0 0 0" xyz="0 0 0"/>
      <inertia ixx="1e-4" ixy="0" ixz="0" iyy="1e-4" iyz="0" izz="1e-4"/>
    </inertial>
    <visual>
      <geometry>
        <mesh filename="meshes/allegro/base_link.obj"/>
      </geometry>
      <origin rpy="0 0 0" xyz="0 0 0 "/>
      <material name="Grey">
        <color rgba="0.2 0.2 0.2 1"/>
      </material>
    </visual>
    <collision>
      <origin rpy="0.0 0 0" xyz="0 0 0"/>
      <geometry>
        <mesh filename="meshes/allegro/base_link.obj"/>
      </geometry>
    </collision>
  </link>
  <gazebo reference="palm_link">
    <material value="Gazebo/Grey"/>
  </gazebo>
  <!-- ============================================================================= -->
  <!-- FINGERS -->
  <!-- RIGHT HAND due to which finger is number 0 -->
  <!-- for LEFT HAND switch the sign of the **offset_origin_y** and **finger_angle_r** parameters-->
  <!-- [LINK 0, 4, 8] -->
  <link name="index_link_0">
    <collision>
      <geometry>
        <mesh filename="meshes/allegro/primary_base.obj"/>
      </geometry>
    </collision>
    <inertial>
      <mass value="0.005"/>
      <origin xyz="0 0 0"/>
      <inertia ixx="5.1458e-05" iyy="5.1458e-05" izz="6.125e-05" ixy="0" ixz="0" iyz="0"/>	
    </inertial>
    <visual>
      <geometry>
        <mesh filename="meshes/allegro/primary_base.obj"/>
      </geometry>
      <material name="Grey">
        <color rgba="0.2 0.2 0.2 1"/>
      </material>
    </visual>
  </link>
  <link name="index_link_1">
    <collision>
      <geometry>
        <mesh filename="meshes/allegro/primary_proximal.obj"/>
      </geometry>
    </collision>
    <inertial>
      <mass value="0.125164"/>
      <origin xyz="0.027 0 0"/>
      <inertia ixx="6.39979e-06" iyy="8.88687e-05" izz="9.13751e-05" ixy="-3.26531e-06" ixz="1.23963e-05" iyz="2.07384e-05"/>	
    </inertial>
    <visual>
      <geometry>
        <mesh filename="meshes/allegro/primary_proximal.obj"/>
      </geometry>
      <material name="Grey">
        <color rgba="0.2 0.2 0.2 1"/>
      </material>
    </visual>
  </link>
  <link name="index_link_2">
    <collision>
      <geometry>
        <mesh filename="meshes/allegro/primary_medial.obj"/>
      </geometry>
    </collision>
    <inertial>
      <mass value="0.131691"/>
      <origin xyz="0.039 0 0"/>
      <inertia ixx="7.04217e-05" iyy="3.95744e-05" izz="6.61125e-05" ixy="-9.64342e-05" ixz="5.8796e-05" iyz="-3.62996e-05"/>	
    </inertial>
    <visual>
      <geometry>
        <mesh filename="meshes/allegro/primary_medial.obj"/>
      </geometry>
      <material name="Grey">
        <color rgba="0.2 0.2 0.2 1"/>
      </material>
    </visual>
  </link>
  <link name="index_link_3">
    <collision>
      <geometry>
        <mesh filename="meshes/biotac/biotac_sensor.obj"/>
      </geometry>
    </collision>
    <inertial>
      <mass value="0.0211922"/>
      <origin xyz="0.029 0 0"/>
      <inertia ixx="2.93743e-05" iyy="7.21391e-05" izz="7.59731e-05" ixy="-3.51896e-05" ixz="-6.31225e-05" iyz="-9.25392e-07"/>
    </inertial>
    <visual>
      <geometry>
        <mesh filename="meshes/biotac/biotac_sensor.obj"/>
      </geometry>
      <material name="Green">
        <color rgba="0. 0.5 0. 1"/>
      </material>
    </visual>
  </link>
  <link name="middle_link_0">
    <collision>
      <geometry>
        <mesh filename="meshes/allegro/primary_base.obj"/>
      </geometry>
    </collision>
    <inertial>
      <mass value="0.005"/>
      <origin xyz="0 0 0"/>
      <inertia ixx="5.1458e-05" iyy="5.1458e-05" izz="6.125e-05" ixy="0" ixz="0" iyz="0"/>	
    </inertial>
    <visual>
      <geometry>
        <mesh filename="meshes/allegro/primary_base.obj"/>
      </geometry>
      <material name="Grey">
        <color rgba="0.2 0.2 0.2 1"/>
      </material>
    </visual>
  </link>
  <link name="middle_link_1">
    <collision>
      <geometry>
        <mesh filename="meshes/allegro/primary_proximal.obj"/>
      </geometry>
    </collision>
    <inertial>
      <mass value="0.125164"/>
      <origin xyz="0.027 0 0"/>
      <inertia ixx="6.39979e-06" iyy="8.88687e-05" izz="9.13751e-05" ixy="-3.26531e-06" ixz="1.23963e-05" iyz="2.07384e-05"/>	
    </inertial>
    <visual>
      <geometry>
        <mesh filename="meshes/allegro/primary_proximal.obj"/>
      </geometry>
      <material name="Grey">
        <color rgba="0.2 0.2 0.2 1"/>
      </material>
    </visual>
  </link>
  <link name="middle_link_2">
    <collision>
      <geometry>
        <mesh filename="meshes/allegro/primary_medial.obj"/>
      </geometry>
    </collision>
    <inertial>
      <mass value="0.131691"/>
      <origin xyz="0.039 0 0"/>
      <inertia ixx="7.04217e-05" iyy="3.95744e-05" izz="6.61125e-05" ixy="-9.64342e-05" ixz="5.8796e-05" iyz="-3.62996e-05"/>	
    </inertial>
    <visual>
      <geometry>
        <mesh filename="meshes/allegro/primary_medial.obj"/>
      </geometry>
      <material name="Grey">
        <color rgba="0.2 0.2 0.2 1"/>
      </material>
    </visual>
  </link>
  <link name="middle_link_3">
    <collision>
      <geometry>
        <mesh filename="meshes/biotac/biotac_sensor.obj"/>
      </geometry>
    </collision>
    <inertial>
      <mass value="0.0211922"/>
      <origin xyz="0.029 0 0"/>
      <inertia ixx="2.93743e-05" iyy="7.21391e-05" izz="7.59731e-05" ixy="-3.51896e-05" ixz="-6.31225e-05" iyz="-9.25392e-07"/>
    </inertial>
    <visual>
      <geometry>
        <mesh filename="meshes/biotac/biotac_sensor.obj"/>
      </geometry>
      <material name="Green">
        <color rgba="0 0.5 0 1"/>
      </material>
    </visual>
  </link>
  <link name="ring_link_0">
    <collision>
      <geometry>
        <mesh filename="meshes/allegro/primary_base.obj"/>
      </geometry>
    </collision>
    <inertial>
      <mass value="0.005"/>
      <origin xyz="0 0 0"/>
      <inertia ixx="5.1458e-05" iyy="5.1458e-05" izz="6.125e-05" ixy="0" ixz="0" iyz="0"/>	
    </inertial>
    <visual>
      <geometry>
        <mesh filename="meshes/allegro/primary_base.obj"/>
      </geometry>
      <material name="Grey">
        <color rgba="0.2 0.2 0.2 1"/>
      </material>
    </visual>
  </link>
  <link name="ring_link_1">
    <collision>
      <geometry>
        <mesh filename="meshes/allegro/primary_proximal.obj"/>
      </geometry>
    </collision>
    <inertial>
      <mass value="0.125164"/>
      <origin xyz="0.027 0 0"/>
      <inertia ixx="6.39979e-06" iyy="8.88687e-05" izz="9.13751e-05" ixy="-3.26531e-06" ixz="1.23963e-05" iyz="2.07384e-05"/>	
    </inertial>
    <visual>
      <geometry>
        <mesh filename="meshes/allegro/primary_proximal.obj"/>
      </geometry>
      <material name="Grey">
        <color rgba="0.2 0.2 0.2 1"/>
      </material>
    </visual>
  </link>
  <link name="ring_link_2">
    <collision>
      <geometry>
        <mesh filename="meshes/allegro/primary_medial.obj"/>
      </geometry>
    </collision>
    <inertial>
      <mass value="0.131691"/>
      <origin xyz="0.039 0 0"/>
      <inertia ixx="7.04217e-05" iyy="3.95744e-05" izz="6.61125e-05" ixy="-9.64342e-05" ixz="5.8796e-05" iyz="-3.62996e-05"/>	
    </inertial>
    <visual>
      <geometry>
        <mesh filename="meshes/allegro/primary_medial.obj"/>
      </geometry>
      <material name="Grey">
        <color rgba="0.2 0.2 0.2 1"/>
      </material>
    </visual>
  </link>
  <link name="ring_link_3">
    <collision>
      <geometry>
        <mesh filename="meshes/biotac/biotac_sensor.obj"/>
      </geometry>
    </collision>
    <inertial>
      <mass value="0.0211922"/>
      <origin xyz="0.029 0 0"/>
      <inertia ixx="2.93743e-05" iyy="7.21391e-05" izz="7.59731e-05" ixy="-3.51896e-05" ixz="-6.31225e-05" iyz="-9.25392e-07"/>
    </inertial>
    <visual>
      <geometry>
        <mesh filename="meshes/biotac/biotac_sensor.obj"/>
      </geometry>
      <material name="Green">
        <color rgba="0 0.5 0 1"/>
      </material>
    </visual>
  </link>
  <link name="thumb_link_0">
    <collision>
      <geometry>
        <mesh filename="meshes/allegro/thumb_base.obj"/>
      </geometry>
    </collision>
    <inertial>
      <mass value="0.1"/>
      <inertia ixx="5.1458e-5" ixy="0" ixz="0" iyy="5.1458e-5" iyz="0" izz="6.125e-5"/>
    </inertial>
    <visual>
      <geometry>
        <mesh filename="meshes/allegro/thumb_base.obj"/>
      </geometry>
      <material name="Grey">
        <color rgba="0.2 0.2 0.2 1"/>
      </material>
    </visual>
  </link>
  <link name="thumb_link_1">
    <collision>
      <geometry>
        <mesh filename="meshes/allegro/thumb_proximal.obj"/>
      </geometry>
    </collision>
    <inertial>
      <mass value="0.1"/>
      <inertia ixx="5.1458e-5" ixy="0" ixz="0" iyy="5.1458e-5" iyz="0" izz="6.125e-5"/>
    </inertial>
    <visual>
      <geometry>
        <mesh filename="meshes/allegro/thumb_proximal.obj"/>
      </geometry>
      <material name="Grey">
        <color rgba="0.2 0.2 0.2 1"/>
      </material>
    </visual>
  </link>
  <link name="thumb_link_2">
    <collision>
      <geometry>
        <mesh filename="meshes/allegro/thumb_medial.obj"/>
      </geometry>
    </collision>
    <inertial>
      <mass value="0.1"/>
      <inertia ixx="5.1458e-5" ixy="0" ixz="0" iyy="5.1458e-5" iyz="0" izz="6.125e-5"/>
    </inertial>
    <visual>
      <geometry>
        <mesh filename="meshes/allegro/thumb_medial.obj"/>
      </geometry>
      <material name="Grey">
        <color rgba="0.2 0.2 0.2 1"/>
      </material>
    </visual>
  </link>
  <link name="thumb_link_3">
    <collision>
      <geometry>
        <mesh filename="meshes/biotac/biotac_sensor_thumb.obj"/>
      </geometry>
    </collision>
    <inertial>
      <mass value="0.1"/>
      <inertia ixx="5.1458e-5" ixy="0" ixz="0" iyy="5.1458e-5" iyz="0" izz="6.125e-5"/>
    </inertial>
    <visual>
      <geometry>
        <mesh filename="meshes/biotac/biotac_sensor_thumb.obj"/>
      </geometry>
      <material name="Green">
        <color rgba="0 0.5 0 1"/>
      </material>
    </visual>
  </link>
  <joint name="index_joint_0" type="revolute">
    <axis xyz="0 0 1"/>
    <limit effort="0.35" lower="-0.558488888889" upper="0.558488888889" velocity="6.283"/>
    <origin rpy="3.1415 -1.57075 -0.0872638888889" xyz="0.0514302 -0.03632 -0.0113"/>
    <parent link="palm_link"/>
    <child link="index_link_0"/>
    <dynamics damping="0.0414019" friction="0.0523963"/>
  </joint>
  <joint name="index_joint_1" type="revolute">
    <axis xyz="0 0 1"/>
    <limit effort="0.35" lower="-0.279244444444" upper="1.727825" velocity="6.283"/>
    <origin rpy="3.1415 -1.57075 1.57075" xyz="0.0 0.0 0.0"/>
    <parent link="index_link_0"/>
    <child link="index_link_1"/>
    <dynamics damping="0.00587541" friction="0.0150275"/>
  </joint>
  <joint name="index_joint_2" type="revolute">
    <axis xyz="0 0 1"/>
    <limit effort="0.35" lower="-0.279244444444" upper="1.727825" velocity="6.283"/>
    <origin rpy="0.0 0.0 0.0" xyz="0.054 0.0 0.0"/>
    <parent link="index_link_1"/>
    <child link="index_link_2"/>
    <dynamics damping="0.010638" friction="0.00616359"/>
  </joint>
  <joint name="index_joint_3" type="revolute">
    <axis xyz="0 0 1"/>
    <limit effort="0.35" lower="-0.279244444444" upper="1.727825" velocity="6.283"/>
    <origin rpy="0.0 0.0 0.0" xyz="0.0384 0.0 0.0"/>
    <parent link="index_link_2"/>
    <child link="index_link_3"/>
    <dynamics damping="0.0226948" friction="0.0227036"/>
  </joint>
  <joint name="middle_joint_0" type="revolute">
    <axis xyz="0 0 1"/>
    <limit effort="0.35" lower="-0.558488888889" upper="0.558488888889" velocity="6.283"/>
    <origin rpy="3.1415 -1.57075 0" xyz="0.0537375 0.0087771 -0.0113"/>
    <parent link="palm_link"/>
    <child link="middle_link_0"/>
    <dynamics damping="0.0414019" friction="0.0523963"/>
  </joint>
  <joint name="middle_joint_1" type="revolute">
    <axis xyz="0 0 1"/>
    <limit effort="0.35" lower="-0.279244444444" upper="1.727825" velocity="6.283"/>
    <origin rpy="3.1415 -1.57075 1.57075" xyz="0.0 0.0 0.0"/>
    <parent link="middle_link_0"/>
    <child link="middle_link_1"/>
    <dynamics damping="0.00587541" friction="0.0150275"/>
  </joint>
  <joint name="middle_joint_2" type="revolute">
    <axis xyz="0 0 1"/>
    <limit effort="0.35" lower="-0.279244444444" upper="1.727825" velocity="6.283"/>
    <origin rpy="0.0 0.0 0.0" xyz="0.054 0.0 0.0"/>
    <parent link="middle_link_1"/>
    <child link="middle_link_2"/>
    <dynamics damping="0.010638" friction="0.00616359"/>
  </joint>
  <joint name="middle_joint_3" type="revolute">
    <axis xyz="0 0 1"/>
    <limit effort="0.35" lower="-0.279244444444" upper="1.727825" velocity="6.283"/>
    <origin rpy="0.0 0.0 0.0" xyz="0.0384 0.0 0.0"/>
    <parent link="middle_link_2"/>
    <child link="middle_link_3"/>
    <dynamics damping="0.0226948" friction="0.0227036"/>
  </joint>
  <joint name="ring_joint_0" type="revolute">
    <axis xyz="0 0 1"/>
    <limit effort="0.35" lower="-0.558488888889" upper="0.558488888889" velocity="6.283"/>
    <origin rpy="3.1415 -1.57075 0.0872638888889" xyz="0.0514302 0.0538749 -0.0113"/>
    <parent link="palm_link"/>
    <child link="ring_link_0"/>
    <dynamics damping="0.0414019" friction="0.0523963"/>
  </joint>
  <joint name="ring_joint_1" type="revolute">
    <axis xyz="0 0 1"/>
    <limit effort="0.35" lower="-0.279244444444" upper="1.727825" velocity="6.283"/>
    <origin rpy="3.1415 -1.57075 1.57075" xyz="0.0 0.0 0.0"/>
    <parent link="ring_link_0"/>
    <child link="ring_link_1"/>
    <dynamics damping="0.00587541" friction="0.0150275"/>
  </joint>
  <joint name="ring_joint_2" type="revolute">
    <axis xyz="0 0 1"/>
    <limit effort="0.35" lower="-0.279244444444" upper="1.727825" velocity="6.283"/>
    <origin rpy="0.0 0.0 0.0" xyz="0.054 0.0 0.0"/>
    <parent link="ring_link_1"/>
    <child link="ring_link_2"/>
    <dynamics damping="0.010638" friction="0.00616359"/>
  </joint>
  <joint name="ring_joint_3" type="revolute">
    <axis xyz="0 0 1"/>
    <limit effort="0.35" lower="-0.279244444444" upper="1.727825" velocity="6.283"/>
    <origin rpy="0.0 0.0 0.0" xyz="0.0384 0.0 0.0"/>
    <parent link="ring_link_2"/>
    <child link="ring_link_3"/>
    <dynamics damping="0.0226948" friction="0.0227036"/>
  </joint>
  <joint name="thumb_joint_0" type="revolute">
    <axis xyz="0 0 1"/>
    <limit effort="0.35" lower="0.279244444444" upper="1.57075" velocity="6.283"/>
    <origin rpy="-1.57075 -1.57075 1.48348611111" xyz="-0.0367482 -0.0081281 -0.0295"/>
    <parent link="palm_link"/>
    <child link="thumb_link_0"/>
    <dynamics friction="0.035"/>
  </joint>
  <joint name="thumb_joint_1" type="revolute">
    <axis xyz="0 0 1"/>
    <limit effort="0.35" lower="-0.331602777778" upper="1.15188333333" velocity="6.283"/>
    <origin rpy="1.57075 0 0" xyz="0.005 0.0 0.0"/>
    <parent link="thumb_link_0"/>
    <child link="thumb_link_1"/>
    <dynamics friction="0.035"/>
  </joint>
  <joint name="thumb_joint_2" type="revolute">
    <axis xyz="0 0 1"/>
    <limit effort="0.35" lower="-0.279244444444" upper="1.727825" velocity="6.283"/>
    <origin rpy="3.1415 -1.57075 0.0" xyz="0 0 0.0554"/>
    <parent link="thumb_link_1"/>
    <child link="thumb_link_2"/>
    <dynamics friction="0.035"/>
  </joint>
  <joint name="thumb_joint_3" type="revolute">
    <axis xyz="0 0 1"/>
    <limit effort="0.35" lower="-0.279244444444" upper="1.76273055556" velocity="6.283"/>
    <origin rpy="0.0 0.0 0.0" xyz="0.0514 0.0 0.0"/>
    <parent link="thumb_link_2"/>
    <child link="thumb_link_3"/>
    <dynamics friction="0.035"/>
  </joint>
  <!-- ============================================================================= -->

</robot>
