<?xml version="1.0" ?>
<!-- =================================================================================== -->
<!-- |    This document was autogenerated by xacro from ur_description/urdf/ur10e.xacro | -->
<!-- |    EDITING THIS FILE BY HAND IS NOT RECOMMENDED                                 | -->
<!-- =================================================================================== -->
<robot name="ur10e_with_shadow">
  <!--
    Base UR robot series xacro macro.

    NOTE: this is NOT a URDF. It cannot directly be loaded by consumers
    expecting a flattened '.urdf' file. See the top-level '.xacro' for that
    (but note: that .xacro must still be processed by the xacro command).

    For use in '.launch' files: use one of the 'load_urX.launch' convenience
    launch files.

    This file models the base kinematic chain of a UR robot, which then gets
    parameterised by various configuration files to convert it into a UR3(e),
    UR5(e), UR10(e) or UR16e.

    NOTE: the default kinematic parameters (ie: link lengths, frame locations,
    offets, etc) do not correspond to any particular robot. They are defaults
    only. There WILL be non-zero offsets between the Forward Kinematics results
    in TF (ie: robot_state_publisher) and the values reported by the Teach
    Pendant.

    For accurate (and robot-specific) transforms, the 'kinematics_parameters_file'
    parameter MUST point to a .yaml file containing the appropriate values for
    the targetted robot.

    If using the UniversalRobots/Universal_Robots_ROS_Driver, follow the steps
    described in the readme of that repository to extract the kinematic
    calibration from the controller and generate the required .yaml file.

    Main author of the migration to yaml configs: Ludovic Delval.

    Contributors to previous versions (in no particular order):

     - Felix Messmer
     - Kelsey Hawkins
     - Wim Meeussen
     - Shaun Edwards
     - Nadia Hammoudeh Garcia
     - Dave Hershberger
     - G. vd. Hoorn
     - Philip Long
     - Dave Coleman
     - Miguel Prada
     - Mathias Luedtke
     - Marcel Schnirring
     - Felix von Drigalski
     - Felix Exner
     - Jimmy Da Silva
     - Ajit Krisshna N L
     - Muhammad Asif Rana
  -->
  <!--
    NOTE: the macro defined in this file is NOT part of the public API of this
          package. Users CANNOT rely on this file being available, or stored in
          this location. Nor can they rely on the existence of the macro.
  -->
  
  <!-- links: main serial chain -->
  <link name="base_link"/>

  <link name="base_link_inertia">
    <visual>
      <origin rpy="0 0 3.141592653589793" xyz="0 0 0"/>
      <geometry>
        <mesh filename="meshes/ur10e/visual_simplified/base.dae"/>
      </geometry>
      <material name="LightGrey">
        <color rgba="0.7 0.7 0.7 1.0"/>
      </material>
    </visual>
    <collision>
      <origin rpy="0 0 3.141592653589793" xyz="0 0 0"/>
      <geometry>
        <mesh filename="meshes/ur10e/collision/base.stl"/>
      </geometry>
    </collision>
    <inertial>
      <mass value="4.0"/>
      <origin rpy="0 0 0" xyz="0 0 0"/>
      <inertia ixx="0.0061063308908" ixy="0.0" ixz="0.0" iyy="0.0061063308908" iyz="0.0" izz="0.01125"/>
    </inertial>
  </link>
  <joint name="base_link_base_link_inertia" type="fixed">
    <parent link="base_link"/>
    <child link="base_link_inertia"/>
    <origin rpy="0 0 0" xyz="0 0 0"/>
  </joint>

  <link name="shoulder_link">
    <visual>
      <origin rpy="0 0 3.141592653589793" xyz="0 0 0"/>
      <geometry>
        <mesh filename="meshes/ur10e/visual_simplified/shoulder.dae"/>
      </geometry>
      <material name="LightGrey">
        <color rgba="0.7 0.7 0.7 1.0"/>
      </material>
    </visual>
    <collision>
      <origin rpy="0 0 3.141592653589793" xyz="0 0 0"/>
      <geometry>
        <mesh filename="meshes/ur10e/collision/shoulder.stl"/>
      </geometry>
    </collision>
    <inertial>
      <mass value="7.778"/>
      <origin rpy="0 0 0" xyz="0 0 0"/>
      <inertia ixx="0.03147431257693659" ixy="0.0" ixz="0.0" iyy="0.03147431257693659" iyz="0.0" izz="0.021875624999999996"/>
    </inertial>
  </link>
  <link name="upper_arm_link">
    <visual>
      <origin rpy="1.5707963267948966 0 -1.5707963267948966" xyz="0 0 0.1762"/>
      <geometry>
        <mesh filename="meshes/ur10e/visual_simplified/upperarm.dae"/>
      </geometry>
      <material name="LightGrey">
        <color rgba="0.7 0.7 0.7 1.0"/>
      </material>
    </visual>
    <collision>
      <origin rpy="1.5707963267948966 0 -1.5707963267948966" xyz="0 0 0.1762"/>
      <geometry>
        <mesh filename="meshes/ur10e/collision/upperarm.stl"/>
      </geometry>
    </collision>
    <inertial>
      <mass value="12.93"/>
      <origin rpy="0 1.5707963267948966 0" xyz="-0.306 0.0 0.175"/>
      <inertia ixx="0.42175380379841093" ixy="0.0" ixz="0.0" iyy="0.42175380379841093" iyz="0.0" izz="0.03636562499999999"/>
    </inertial>
  </link>
  <link name="forearm_link">
    <visual>
      <origin rpy="1.5707963267948966 0 -1.5707963267948966" xyz="0 0 0.0393"/>
      <geometry>
        <mesh filename="meshes/ur10e/visual_simplified/forearm.dae"/>
      </geometry>
      <material name="LightGrey">
        <color rgba="0.7 0.7 0.7 1.0"/>
      </material>
    </visual>
    <collision>
      <origin rpy="1.5707963267948966 0 -1.5707963267948966" xyz="0 0 0.0393"/>
      <geometry>
        <mesh filename="meshes/ur10e/collision/forearm.stl"/>
      </geometry>
    </collision>
    <inertial>
      <mass value="3.87"/>
      <origin rpy="0 1.5707963267948966 0" xyz="-0.285775 0.0 0.0393"/>
      <inertia ixx="0.11079302548902206" ixy="0.0" ixz="0.0" iyy="0.11079302548902206" iyz="0.0" izz="0.010884375"/>
    </inertial>
  </link>
  <link name="wrist_1_link">
    <visual>
      <!-- TODO: Move this to a parameter -->
      <origin rpy="1.5707963267948966 0 0" xyz="0 0 -0.135"/>
      <geometry>
        <mesh filename="meshes/ur10e/visual_simplified/wrist1.dae"/>
      </geometry>
      <material name="LightGrey">
        <color rgba="0.7 0.7 0.7 1.0"/>
      </material>
    </visual>
    <collision>
      <origin rpy="1.5707963267948966 0 0" xyz="0 0 -0.135"/>
      <geometry>
        <mesh filename="meshes/ur10e/collision/wrist1.stl"/>
      </geometry>
    </collision>
    <inertial>
      <mass value="1.96"/>
      <origin rpy="0 0 0" xyz="0 0 0"/>
      <inertia ixx="0.005108247956699999" ixy="0.0" ixz="0.0" iyy="0.005108247956699999" iyz="0.0" izz="0.005512499999999999"/>
    </inertial>
  </link>
  <link name="wrist_2_link">
    <visual>
      <origin rpy="0 0 0" xyz="0 0 -0.12"/>
      <geometry>
        <mesh filename="meshes/ur10e/visual_simplified/wrist2.dae"/>
      </geometry>
      <material name="LightGrey">
        <color rgba="0.7 0.7 0.7 1.0"/>
      </material>
    </visual>
    <collision>
      <origin rpy="0 0 0" xyz="0 0 -0.12"/>
      <geometry>
        <mesh filename="meshes/ur10e/collision/wrist2.stl"/>
      </geometry>
    </collision>
    <inertial>
      <mass value="1.96"/>
      <origin rpy="0 0 0" xyz="0 0 0"/>
      <inertia ixx="0.005108247956699999" ixy="0.0" ixz="0.0" iyy="0.005108247956699999" iyz="0.0" izz="0.005512499999999999"/>
    </inertial>
  </link>
  <link name="wrist_3_link">
    <visual>
      <origin rpy="1.5707963267948966 0 0" xyz="0 0 -0.1168"/>
      <geometry>
        <mesh filename="meshes/ur10e/visual_simplified/wrist3.dae"/>
      </geometry>
      <material name="LightGrey">
        <color rgba="0.7 0.7 0.7 1.0"/>
      </material>
    </visual>
    <collision>
      <origin rpy="1.5707963267948966 0 0" xyz="0 0 -0.1168"/>
      <geometry>
        <mesh filename="meshes/ur10e/collision/wrist3.stl"/>
      </geometry>
    </collision>
    <inertial>
      <mass value="0.202"/>
      <origin rpy="0 0 0" xyz="0.0 0.0 -0.025"/>
      <inertia ixx="0.00014434577559500002" ixy="0.0" ixz="0.0" iyy="0.00014434577559500002" iyz="0.0" izz="0.00020452500000000002"/>
    </inertial>
  </link>
  
  
  <joint name="shoulder_pan_joint" type="revolute">
    <parent link="base_link_inertia"/>
    <child link="shoulder_link"/>
    <origin rpy="0 0 0" xyz="0 0 0.1807"/>
    <axis xyz="0 0 1"/>
    <limit effort="330.0" lower="-6.283185307179586" upper="6.283185307179586" velocity="2.0943951023931953"/>
    <dynamics damping="0" friction="0"/>
  </joint>
  <joint name="shoulder_lift_joint" type="revolute">
    <parent link="shoulder_link"/>
    <child link="upper_arm_link"/>
    <origin rpy="1.570796327 0 0" xyz="0 0 0"/>
    <axis xyz="0 0 1"/>
    <limit effort="330.0" lower="-6.283185307179586" upper="6.283185307179586" velocity="2.0943951023931953"/>
    <dynamics damping="0" friction="0"/>
  </joint>
  <joint name="elbow_joint" type="revolute">
    <parent link="upper_arm_link"/>
    <child link="forearm_link"/>
    <origin rpy="0 0 0" xyz="-0.6127 0 0"/>
    <axis xyz="0 0 1"/>
    <limit effort="150.0" lower="-3.141592653589793" upper="3.141592653589793" velocity="3.141592653589793"/>
    <dynamics damping="0" friction="0"/>
  </joint>
  <joint name="wrist_1_joint" type="revolute">
    <parent link="forearm_link"/>
    <child link="wrist_1_link"/>
    <origin rpy="0 0 0" xyz="-0.57155 0 0.17415"/>
    <axis xyz="0 0 1"/>
    <limit effort="56.0" lower="-6.283185307179586" upper="6.283185307179586" velocity="3.141592653589793"/>
    <dynamics damping="0" friction="0"/>
  </joint>
  <joint name="wrist_2_joint" type="revolute">
    <parent link="wrist_1_link"/>
    <child link="wrist_2_link"/>
    <origin rpy="1.570796327 0 0" xyz="0 -0.11985 -2.458164590756244e-11"/>
    <axis xyz="0 0 1"/>
    <limit effort="56.0" lower="-6.283185307179586" upper="6.283185307179586" velocity="3.141592653589793"/>
    <dynamics damping="0" friction="0"/>
  </joint>
  <joint name="wrist_3_joint" type="revolute">
    <parent link="wrist_2_link"/>
    <child link="wrist_3_link"/>
    <origin rpy="1.570796326589793 3.141592653589793 3.141592653589793" xyz="0 0.11655 -2.390480459346185e-11"/>
    <axis xyz="0 0 1"/>
    <limit effort="56.0" lower="-6.283185307179586" upper="6.283185307179586" velocity="3.141592653589793"/>
    <dynamics damping="0" friction="0"/>
  </joint>

  <link name="flange"/>
  <joint name="wrist_3-flange" type="fixed">
    <parent link="wrist_3_link"/>
    <child link="flange"/>
    <origin rpy="0 -1.5707963267948966 -1.5707963267948966" xyz="0 0 0"/>
  </joint>
  <joint name="flange-rh_forearm" type="fixed">
    <origin xyz="-0.0167 0 0" rpy="3.141592653589793 -1.5707963267948966 0.0"/> <!-- 根据实际情况调整手掌在末端执行器上的位置和姿态 -->
    <parent link="flange"/>
    <child link="rh_forearm"/>
</joint>

<!--BeginRightADD-->
   <link name="rh_forearm">
      <!-- <visual name="forearm_0">
         <origin xyz="-0.0006274281916165553 2.5023159453650283e-05 0.006174842104832059" rpy="1.2117729232060683 -1.5707754380241972 1.9125508984262103"/>
         <geometry>
            <mesh filename="stl/forearm_0.stl"/>
         </geometry>
         <material name="white"/>
      </visual> -->
      <visual name="forearm_1">
         <origin xyz="0.000893298872235559 4.97185265354338e-07 0.10642138763934732" rpy="0.04194673297001396 -0.0002782271006374071 1.5768021406033002"/>
         <geometry>
            <mesh filename="stl/forearm_1.stl"/>
         </geometry>
         <material name="white"/>
      </visual>
      <!-- <visual name="forearm_collision">
         <origin xyz="-2.3000312765045747e-08 -2.164897719253595e-08 0.0927456223223767" rpy="0.0 0.0 0.0"/>
         <geometry>
            <mesh filename="stl/forearm_collision.stl"/>
         </geometry>
         <material name="white"/>
      </visual> -->
   </link>
   <link name="rh_wrist">
      <visual name="wrist">
         <origin xyz="0.0026493678443454513 2.2619274745282502e-05 0.01606431384985827" rpy="1.5546762010448698 -0.0015692253144186097 1.5706727051126772"/>
         <geometry>
            <mesh filename="stl/right_wrist.stl"/>
         </geometry>
         <material name="white"/>
      </visual>
   </link>
   <joint type="revolute" name="rh_WRJ2">
      <parent link="rh_forearm"/>
      <child link="rh_wrist"/>
      <origin xyz="0.01 0.0 0.21301" rpy="0.0 0.0 1.5707963267948963"/>
      <axis xyz="0.0 1.0 0.0"/>
      <limit lower="-0.523599" upper="0.174533" effort="100" velocity="100"/>
   </joint>
   <link name="rh_palm">
      <visual name="palm">
         <origin xyz="0.005374445170477271 -0.0022442906559082794 0.03201294312033412" rpy="0.2100458392356129 0.08313278223257159 1.5503210950325148"/>
         <geometry>
            <mesh filename="stl/right_palm.stl"/>
         </geometry>
         <material name="white"/>
      </visual>
   </link>
   <joint type="revolute" name="rh_WRJ1">
      <parent link="rh_wrist"/>
      <child link="rh_palm"/>
      <origin xyz="0.0 0.0 0.034" rpy="0.0 0.0 0.0"/>
      <axis xyz="1.0 0.0 0.0"/>
      <limit lower="-0.698132" upper="0.488692" effort="100" velocity="100"/>
   </joint>
   <link name="rh_ffknuckle">
      <visual name="f_knuckle">
         <origin xyz="-8.015943942283821e-06 0.00028383334511582203 0.0003141144870240873" rpy="0.4761390295154802 0.007276744315003247 -0.01128884895567703"/>
         <geometry>
            <mesh filename="stl/f_knuckle.stl"/>
         </geometry>
         <material name="white"/>
      </visual>
   </link>
   <joint type="revolute" name="rh_FFJ4">
      <parent link="rh_palm"/>
      <child link="rh_ffknuckle"/>
      <origin xyz="0.033 0.0 0.095" rpy="0.0 0.0 0.0"/>
      <axis xyz="0.0 -1.0 0.0"/>
      <limit lower="-0.349066" upper="0.349066" effort="100" velocity="100"/>
   </joint>
   <link name="rh_ffproximal">
      <visual name="f_proximal">
         <origin xyz="1.2104673000657597e-06 9.76175282387983e-06 0.022880653343431333" rpy="-7.135757573614219e-06 0.01189393423812235 1.5705980355726104"/>
         <geometry>
            <mesh filename="stl/f_proximal.stl"/>
         </geometry>
         <material name="white"/>
      </visual>
   </link>
   <joint type="revolute" name="rh_FFJ3">
      <parent link="rh_ffknuckle"/>
      <child link="rh_ffproximal"/>
      <origin xyz="0.0 0.0 0.0" rpy="0.0 0.0 0.0"/>
      <axis xyz="1.0 0.0 0.0"/>
      <limit lower="-0.261799" upper="1.5708" effort="100" velocity="100"/>
   </joint>
   <link name="rh_ffmiddle">
      <visual name="f_middle">
         <origin xyz="-2.7197407046965675e-06 -3.219283283025054e-05 0.011511409944870538" rpy="-1.5154077996843905e-05 -0.00025673504362555555 1.5707963267948966"/>
         <geometry>
            <mesh filename="stl/f_middle.stl"/>
         </geometry>
         <material name="white"/>
      </visual>
   </link>
   <joint type="revolute" name="rh_FFJ2">
      <parent link="rh_ffproximal"/>
      <child link="rh_ffmiddle"/>
      <origin xyz="0.0 0.0 0.045" rpy="0.0 0.0 0.0"/>
      <axis xyz="1.0 0.0 0.0"/>
      <limit lower="0.0" upper="1.5708" effort="100" velocity="100"/>
   </joint>
   <link name="rh_ffdistal">
      <visual name="f_distal_pst">
         <origin xyz="-2.398434946392576e-05 0.00042073257364413626 0.017646475317320408" rpy="1.9593220200595154e-05 0.002689843516656243 1.582276007411751"/>
         <geometry>
            <mesh filename="stl/f_distal_pst.stl"/>
         </geometry>
         <material name="white"/>
      </visual>
   </link>
   <joint type="revolute" name="rh_FFJ1">
      <parent link="rh_ffmiddle"/>
      <child link="rh_ffdistal"/>
      <origin xyz="0.0 0.0 0.025" rpy="0.0 0.0 0.0"/>
      <axis xyz="1.0 0.0 0.0"/>
      <limit lower="0.0" upper="1.5708" effort="100" velocity="100"/>
   </joint>
   <link name="rh_mfknuckle">
      <visual name="f_knuckle">
         <origin xyz="-8.015943942283821e-06 0.00028383334511582203 0.0003141144870240873" rpy="0.4761390295154802 0.007276744315003247 -0.01128884895567703"/>
         <geometry>
            <mesh filename="stl/f_knuckle.stl"/>
         </geometry>
         <material name="white"/>
      </visual>
   </link>
   <joint type="revolute" name="rh_MFJ4">
      <parent link="rh_palm"/>
      <child link="rh_mfknuckle"/>
      <origin xyz="0.011 0.0 0.099" rpy="0.0 0.0 0.0"/>
      <axis xyz="0.0 -1.0 0.0"/>
      <limit lower="-0.349066" upper="0.349066" effort="100" velocity="100"/>
   </joint>
   <link name="rh_mfproximal">
      <visual name="f_proximal">
         <origin xyz="1.2104673000657597e-06 9.76175282387983e-06 0.022880653343431333" rpy="-7.135757573614219e-06 0.01189393423812235 1.5705980355726104"/>
         <geometry>
            <mesh filename="stl/f_proximal.stl"/>
         </geometry>
         <material name="white"/>
      </visual>
   </link>
   <joint type="revolute" name="rh_MFJ3">
      <parent link="rh_mfknuckle"/>
      <child link="rh_mfproximal"/>
      <origin xyz="0.0 0.0 0.0" rpy="0.0 0.0 0.0"/>
      <axis xyz="1.0 0.0 0.0"/>
      <limit lower="-0.261799" upper="1.5708" effort="100" velocity="100"/>
   </joint>
   <link name="rh_mfmiddle">
      <visual name="f_middle">
         <origin xyz="-2.7197407046965675e-06 -3.219283283025054e-05 0.011511409944870538" rpy="-1.5154077996843905e-05 -0.00025673504362555555 1.5707963267948966"/>
         <geometry>
            <mesh filename="stl/f_middle.stl"/>
         </geometry>
         <material name="white"/>
      </visual>
   </link>
   <joint type="revolute" name="rh_MFJ2">
      <parent link="rh_mfproximal"/>
      <child link="rh_mfmiddle"/>
      <origin xyz="0.0 0.0 0.045" rpy="0.0 0.0 0.0"/>
      <axis xyz="1.0 0.0 0.0"/>
      <limit lower="0.0" upper="1.5708" effort="100" velocity="100"/>
   </joint>
   <link name="rh_mfdistal">
      <visual name="f_distal_pst">
         <origin xyz="-2.398434946392576e-05 0.00042073257364413626 0.017646475317320408" rpy="1.9593220200595154e-05 0.002689843516656243 1.582276007411751"/>
         <geometry>
            <mesh filename="stl/f_distal_pst.stl"/>
         </geometry>
         <material name="white"/>
      </visual>
   </link>
   <joint type="revolute" name="rh_MFJ1">
      <parent link="rh_mfmiddle"/>
      <child link="rh_mfdistal"/>
      <origin xyz="0.0 0.0 0.025" rpy="0.0 0.0 0.0"/>
      <axis xyz="1.0 0.0 0.0"/>
      <limit lower="0.0" upper="1.5708" effort="100" velocity="100"/>
   </joint>
   <link name="rh_rfknuckle">
      <visual name="f_knuckle">
         <origin xyz="-8.015943942283821e-06 0.00028383334511582203 0.0003141144870240873" rpy="0.4761390295154802 0.007276744315003247 -0.01128884895567703"/>
         <geometry>
            <mesh filename="stl/f_knuckle.stl"/>
         </geometry>
         <material name="white"/>
      </visual>
   </link>
   <joint type="revolute" name="rh_RFJ4">
      <parent link="rh_palm"/>
      <child link="rh_rfknuckle"/>
      <origin xyz="-0.011 0.0 0.095" rpy="0.0 0.0 0.0"/>
      <axis xyz="0.0 1.0 0.0"/>
      <limit lower="-0.349066" upper="0.349066" effort="100" velocity="100"/>
   </joint>
   <link name="rh_rfproximal">
      <visual name="f_proximal">
         <origin xyz="1.2104673000657597e-06 9.76175282387983e-06 0.022880653343431333" rpy="-7.135757573614219e-06 0.01189393423812235 1.5705980355726104"/>
         <geometry>
            <mesh filename="stl/f_proximal.stl"/>
         </geometry>
         <material name="white"/>
      </visual>
   </link>
   <joint type="revolute" name="rh_RFJ3">
      <parent link="rh_rfknuckle"/>
      <child link="rh_rfproximal"/>
      <origin xyz="0.0 0.0 0.0" rpy="0.0 0.0 0.0"/>
      <axis xyz="1.0 0.0 0.0"/>
      <limit lower="-0.261799" upper="1.5708" effort="100" velocity="100"/>
   </joint>
   <link name="rh_rfmiddle">
      <visual name="f_middle">
         <origin xyz="-2.7197407046965675e-06 -3.219283283025054e-05 0.011511409944870538" rpy="-1.5154077996843905e-05 -0.00025673504362555555 1.5707963267948966"/>
         <geometry>
            <mesh filename="stl/f_middle.stl"/>
         </geometry>
         <material name="white"/>
      </visual>
   </link>
   <joint type="revolute" name="rh_RFJ2">
      <parent link="rh_rfproximal"/>
      <child link="rh_rfmiddle"/>
      <origin xyz="0.0 0.0 0.045" rpy="0.0 0.0 0.0"/>
      <axis xyz="1.0 0.0 0.0"/>
      <limit lower="0.0" upper="1.5708" effort="100" velocity="100"/>
   </joint>
   <link name="rh_rfdistal">
      <visual name="f_distal_pst">
         <origin xyz="-2.398434946392576e-05 0.00042073257364413626 0.017646475317320408" rpy="1.9593220200595154e-05 0.002689843516656243 1.582276007411751"/>
         <geometry>
            <mesh filename="stl/f_distal_pst.stl"/>
         </geometry>
         <material name="white"/>
      </visual>
   </link>
   <joint type="revolute" name="rh_RFJ1">
      <parent link="rh_rfmiddle"/>
      <child link="rh_rfdistal"/>
      <origin xyz="0.0 0.0 0.025" rpy="0.0 0.0 0.0"/>
      <axis xyz="1.0 0.0 0.0"/>
      <limit lower="0.0" upper="1.5708" effort="100" velocity="100"/>
   </joint>
   <link name="rh_lfmetacarpal">
      <visual name="lf_metacarpal">
         <origin xyz="-0.01889428  0.00066234  0.03130367" rpy="-0.8420695670279069 0.04469723682216371 1.565424596377065"/>
         <geometry>
            <mesh filename="stl/right_lf_metacarpal.stl"/>
         </geometry>
         <material name="white"/>
      </visual>
   </link>
   <joint type="revolute" name="rh_LFJ5">
      <parent link="rh_palm"/>
      <child link="rh_lfmetacarpal"/>
      <origin xyz="-0.033 0.0 0.02071" rpy="0 0.6108649061631908 0"/>
      <axis xyz="0 0 1"/>
      <!-- <origin xyz="-0.033 0.0 0.02071" rpy="0.0 0.0 0.0"/>
      <axis xyz="0.5735761643640092 0.0 0.819152234736298"/> -->
      <limit lower="0.0" upper="0.785398" effort="100" velocity="100"/>
   </joint>
   <link name="rh_lfknuckle">
      <visual name="f_knuckle">
         <origin xyz="-8.015943942283821e-06 0.00028383334511582203 0.0003141144870240873" rpy="0.4761390295154802 0.007276744315003247 -0.01128884895567703"/>
         <geometry>
            <mesh filename="stl/f_knuckle.stl"/>
         </geometry>
         <material name="white"/>
      </visual>
   </link>
   <joint type="revolute" name="rh_LFJ4">
      <parent link="rh_lfmetacarpal"/>
      <child link="rh_lfknuckle"/>
       <!-- <origin xyz="0.0 0.0 0.06579" rpy="0.0 0.0 0.0"/> -->
      <origin xyz="-0.03773558 0. 0.05389203" rpy="0 -0.6108649061631908 0"/>
      <axis xyz="0.0 1.0 0.0"/>
      <limit lower="-0.349066" upper="0.349066" effort="100" velocity="100"/>
   </joint>
   <link name="rh_lfproximal">
      <visual name="f_proximal">
         <origin xyz="1.2104673000657597e-06 9.76175282387983e-06 0.022880653343431333" rpy="-7.135757573614219e-06 0.01189393423812235 1.5705980355726104"/>
         <geometry>
            <mesh filename="stl/f_proximal.stl"/>
         </geometry>
         <material name="white"/>
      </visual>
   </link>
   <joint type="revolute" name="rh_LFJ3">
      <parent link="rh_lfknuckle"/>
      <child link="rh_lfproximal"/>
      <origin xyz="0.0 0.0 0.0" rpy="0.0 0.0 0.0"/>
      <axis xyz="1.0 0.0 0.0"/>
      <limit lower="-0.261799" upper="1.5708" effort="100" velocity="100"/>
   </joint>
   <link name="rh_lfmiddle">
      <visual name="f_middle">
         <origin xyz="-2.7197407046965675e-06 -3.219283283025054e-05 0.011511409944870538" rpy="-1.5154077996843905e-05 -0.00025673504362555555 1.5707963267948966"/>
         <geometry>
            <mesh filename="stl/f_middle.stl"/>
         </geometry>
         <material name="white"/>
      </visual>
   </link>
   <joint type="revolute" name="rh_LFJ2">
      <parent link="rh_lfproximal"/>
      <child link="rh_lfmiddle"/>
      <origin xyz="0.0 0.0 0.045" rpy="0.0 0.0 0.0"/>
      <axis xyz="1.0 0.0 0.0"/>
      <limit lower="0.0" upper="1.5708" effort="100" velocity="100"/>
   </joint>
   <link name="rh_lfdistal">
      <visual name="f_distal_pst">
         <origin xyz="-2.398434946392576e-05 0.00042073257364413626 0.017646475317320408" rpy="1.9593220200595154e-05 0.002689843516656243 1.582276007411751"/>
         <geometry>
            <mesh filename="stl/f_distal_pst.stl"/>
         </geometry>
         <material name="white"/>
      </visual>
   </link>
   <joint type="revolute" name="rh_LFJ1">
      <parent link="rh_lfmiddle"/>
      <child link="rh_lfdistal"/>
      <origin xyz="0.0 0.0 0.025" rpy="0.0 0.0 0.0"/>
      <axis xyz="1.0 0.0 0.0"/>
      <limit lower="0.0" upper="1.5708" effort="100" velocity="100"/>
   </joint>
   <link name="rh_thbase"/>
   <joint type="revolute" name="rh_THJ5">
      <parent link="rh_palm"/>
      <child link="rh_thbase"/>
      <origin xyz="0.034 -0.00858 0.029" rpy="0.0 0.7853970066908715 0.0"/>
      <axis xyz="0.0 0.0 -1.0"/>
      <limit lower="-1.0472" upper="1.0472" effort="100" velocity="100"/>
   </joint>
   <link name="rh_thproximal">
      <visual name="th_proximal">
         <origin xyz="-6.378894056540728e-06 -2.6031284627244637e-05 0.016715298411459745" rpy="-4.186875454471058e-06 0.0010962409823094266 0.3847587823606159"/>
         <geometry>
            <mesh filename="stl/th_proximal.stl"/>
         </geometry>
         <material name="white"/>
      </visual>
   </link>
   <joint type="revolute" name="rh_THJ4">
      <parent link="rh_thbase"/>
      <child link="rh_thproximal"/>
      <origin xyz="0.0 0.0 0.0" rpy="0.0 0.0 0.0"/>
      <axis xyz="1.0 0.0 0.0"/>
      <limit lower="0.0" upper="1.22173" effort="100" velocity="100"/>
   </joint>
   <link name="rh_thhub"/>
   <joint type="revolute" name="rh_THJ3">
      <parent link="rh_thproximal"/>
      <child link="rh_thhub"/>
      <origin xyz="0.0 0.0 0.038" rpy="0.0 0.0 0.0"/>
      <axis xyz="1.0 0.0 0.0"/>
      <limit lower="-0.20944" upper="0.20944" effort="100" velocity="100"/>
   </joint>
   <link name="rh_thmiddle">
      <visual name="th_middle">
         <origin xyz="7.479629857400793e-05 -4.506977852869377e-05 0.015348398308984388" rpy="0.0 -0.0009035488116579948 0.0"/>
         <geometry>
            <mesh filename="stl/th_middle.stl"/>
         </geometry>
         <material name="white"/>
      </visual>
   </link>
   <joint type="revolute" name="rh_THJ2">
      <parent link="rh_thhub"/>
      <child link="rh_thmiddle"/>
      <origin xyz="0.0 0.0 0.0" rpy="0.0 0.0 0.0"/>
      <axis xyz="0.0 -1.0 0.0"/>
      <limit lower="-0.698132" upper="0.698132" effort="100" velocity="100"/>
   </joint>
   <link name="rh_thdistal">
      <visual name="th_distal_pst">
         <origin xyz="-8.254509753145168e-07 0.000802518759472585 0.019553373143358997" rpy="-0.0001073181947076323 0.003173495876248822 1.5706693697416252"/>
         <geometry>
            <mesh filename="stl/th_distal_pst.stl"/>
         </geometry>
         <material name="white"/>
      </visual>
   </link>
   <joint type="revolute" name="rh_THJ1">
      <parent link="rh_thmiddle"/>
      <child link="rh_thdistal"/>
      <origin xyz="0.0 0.0 0.032" rpy="0.0 0.0 -1.5707963267948963"/>
      <axis xyz="1.0 0.0 0.0"/>
      <limit lower="-0.261799" upper="1.5708" effort="100" velocity="100"/>
   </joint>
   <material name="white">
      <color rgba="1 1 1 1"/>
   </material>
<!-- OVERADD-->

</robot>
